Traceback (most recent call last):
  File "/scratch/wangyuxuan1/.conda/envs/longva/lib/python3.10/site-packages/huggingface_hub/utils/_errors.py", line 304, in hf_raise_for_status
Traceback (most recent call last):
  File "/scratch/wangyuxuan1/.conda/envs/longva/lib/python3.10/site-packages/huggingface_hub/utils/_errors.py", line 304, in hf_raise_for_status
    response.raise_for_status()
  File "/scratch/wangyuxuan1/.conda/envs/longva/lib/python3.10/site-packages/requests/models.py", line 1024, in raise_for_status
    response.raise_for_status()
  File "/scratch/wangyuxuan1/.conda/envs/longva/lib/python3.10/site-packages/requests/models.py", line 1024, in raise_for_status
    raise HTTPError(http_error_msg, response=self)
    raise HTTPError(http_error_msg, response=self)
requests.exceptions.HTTPError: 404 Client Error: Not Found for url: https://huggingface.co/checkpoints/longva7b-llavanextsub10k-qwen2-ORNS/resolve/main/tokenizer_config.json

The above exception was the direct cause of the following exception:

requests.exceptions.HTTPError: 404 Client Error: Not Found for url: https://huggingface.co/checkpoints/longva7b-llavanextsub10k-qwen2-ORNS/resolve/main/tokenizer_config.json
Traceback (most recent call last):

The above exception was the direct cause of the following exception:

Traceback (most recent call last):
  File "/scratch/wangyuxuan1/.conda/envs/longva/lib/python3.10/site-packages/transformers/utils/hub.py", line 402, in cached_file
  File "/scratch/wangyuxuan1/.conda/envs/longva/lib/python3.10/site-packages/transformers/utils/hub.py", line 402, in cached_file
    resolved_file = hf_hub_download(
    resolved_file = hf_hub_download(
  File "/scratch/wangyuxuan1/.conda/envs/longva/lib/python3.10/site-packages/huggingface_hub/utils/_deprecation.py", line 101, in inner_f
  File "/scratch/wangyuxuan1/.conda/envs/longva/lib/python3.10/site-packages/huggingface_hub/utils/_deprecation.py", line 101, in inner_f
    return f(*args, **kwargs)
  File "/scratch/wangyuxuan1/.conda/envs/longva/lib/python3.10/site-packages/huggingface_hub/utils/_validators.py", line 114, in _inner_fn
    return f(*args, **kwargs)
  File "/scratch/wangyuxuan1/.conda/envs/longva/lib/python3.10/site-packages/huggingface_hub/utils/_validators.py", line 114, in _inner_fn
    return fn(*args, **kwargs)
    return fn(*args, **kwargs)
  File "/scratch/wangyuxuan1/.conda/envs/longva/lib/python3.10/site-packages/huggingface_hub/file_download.py", line 1240, in hf_hub_download
  File "/scratch/wangyuxuan1/.conda/envs/longva/lib/python3.10/site-packages/huggingface_hub/file_download.py", line 1240, in hf_hub_download
    return _hf_hub_download_to_cache_dir(
    return _hf_hub_download_to_cache_dir(
  File "/scratch/wangyuxuan1/.conda/envs/longva/lib/python3.10/site-packages/huggingface_hub/file_download.py", line 1347, in _hf_hub_download_to_cache_dir
  File "/scratch/wangyuxuan1/.conda/envs/longva/lib/python3.10/site-packages/huggingface_hub/file_download.py", line 1347, in _hf_hub_download_to_cache_dir
    _raise_on_head_call_error(head_call_error, force_download, local_files_only)
  File "/scratch/wangyuxuan1/.conda/envs/longva/lib/python3.10/site-packages/huggingface_hub/file_download.py", line 1854, in _raise_on_head_call_error
    _raise_on_head_call_error(head_call_error, force_download, local_files_only)
  File "/scratch/wangyuxuan1/.conda/envs/longva/lib/python3.10/site-packages/huggingface_hub/file_download.py", line 1854, in _raise_on_head_call_error
    raise head_call_error
  File "/scratch/wangyuxuan1/.conda/envs/longva/lib/python3.10/site-packages/huggingface_hub/file_download.py", line 1751, in _get_metadata_or_catch_error
    raise head_call_error
  File "/scratch/wangyuxuan1/.conda/envs/longva/lib/python3.10/site-packages/huggingface_hub/file_download.py", line 1751, in _get_metadata_or_catch_error
    metadata = get_hf_file_metadata(
  File "/scratch/wangyuxuan1/.conda/envs/longva/lib/python3.10/site-packages/huggingface_hub/utils/_validators.py", line 114, in _inner_fn
    metadata = get_hf_file_metadata(
  File "/scratch/wangyuxuan1/.conda/envs/longva/lib/python3.10/site-packages/huggingface_hub/utils/_validators.py", line 114, in _inner_fn
    return fn(*args, **kwargs)
  File "/scratch/wangyuxuan1/.conda/envs/longva/lib/python3.10/site-packages/huggingface_hub/file_download.py", line 1673, in get_hf_file_metadata
    return fn(*args, **kwargs)
  File "/scratch/wangyuxuan1/.conda/envs/longva/lib/python3.10/site-packages/huggingface_hub/file_download.py", line 1673, in get_hf_file_metadata
    r = _request_wrapper(
  File "/scratch/wangyuxuan1/.conda/envs/longva/lib/python3.10/site-packages/huggingface_hub/file_download.py", line 376, in _request_wrapper
    r = _request_wrapper(
  File "/scratch/wangyuxuan1/.conda/envs/longva/lib/python3.10/site-packages/huggingface_hub/file_download.py", line 376, in _request_wrapper
    response = _request_wrapper(
  File "/scratch/wangyuxuan1/.conda/envs/longva/lib/python3.10/site-packages/huggingface_hub/file_download.py", line 400, in _request_wrapper
    response = _request_wrapper(
  File "/scratch/wangyuxuan1/.conda/envs/longva/lib/python3.10/site-packages/huggingface_hub/file_download.py", line 400, in _request_wrapper
    hf_raise_for_status(response)
  File "/scratch/wangyuxuan1/.conda/envs/longva/lib/python3.10/site-packages/huggingface_hub/utils/_errors.py", line 352, in hf_raise_for_status
    hf_raise_for_status(response)
  File "/scratch/wangyuxuan1/.conda/envs/longva/lib/python3.10/site-packages/huggingface_hub/utils/_errors.py", line 352, in hf_raise_for_status
    raise RepositoryNotFoundError(message, response) from e
huggingface_hub.utils._errors.RepositoryNotFoundError: 404 Client Error. (Request ID: Root=1-672a1e83-6e3a89ce00ba22e77ace84d1;e1602550-cc95-48a7-85ba-fa6a9170e15a)

Repository Not Found for url: https://huggingface.co/checkpoints/longva7b-llavanextsub10k-qwen2-ORNS/resolve/main/tokenizer_config.json.
Please make sure you specified the correct `repo_id` and `repo_type`.
If you are trying to access a private or gated repo, make sure you are authenticated.

The above exception was the direct cause of the following exception:

Traceback (most recent call last):
  File "/scratch/wangyuxuan1/.conda/envs/longva/lib/python3.10/runpy.py", line 196, in _run_module_as_main
    raise RepositoryNotFoundError(message, response) from e
huggingface_hub.utils._errors.RepositoryNotFoundError: 404 Client Error. (Request ID: Root=1-672a1e83-2e5362287676dc4541c2346b;80b28479-91ab-4957-9c26-ed5de9028610)

Repository Not Found for url: https://huggingface.co/checkpoints/longva7b-llavanextsub10k-qwen2-ORNS/resolve/main/tokenizer_config.json.
Please make sure you specified the correct `repo_id` and `repo_type`.
If you are trying to access a private or gated repo, make sure you are authenticated.

The above exception was the direct cause of the following exception:

Traceback (most recent call last):
  File "/scratch/wangyuxuan1/.conda/envs/longva/lib/python3.10/runpy.py", line 196, in _run_module_as_main
    return _run_code(code, main_globals, None,
  File "/scratch/wangyuxuan1/.conda/envs/longva/lib/python3.10/runpy.py", line 86, in _run_code
    return _run_code(code, main_globals, None,
  File "/scratch/wangyuxuan1/.conda/envs/longva/lib/python3.10/runpy.py", line 86, in _run_code
    exec(code, run_globals)
  File "/scratch/nlp/patrick/codes/OminousLLM/intersuit/longva/eval/model_videoqa_mc.py", line 243, in <module>
    exec(code, run_globals)
  File "/scratch/nlp/patrick/codes/OminousLLM/intersuit/longva/eval/model_videoqa_mc.py", line 243, in <module>
    run_inference(args)
  File "/scratch/nlp/patrick/codes/OminousLLM/intersuit/longva/eval/model_videoqa_mc.py", line 134, in run_inference
    run_inference(args)
  File "/scratch/nlp/patrick/codes/OminousLLM/intersuit/longva/eval/model_videoqa_mc.py", line 134, in run_inference
    tokenizer, model, image_processor, _ = load_pretrained_model(args.model_path, args.model_base, model_name, device_map="auto")
  File "/scratch/nlp/patrick/codes/OminousLLM/intersuit/longva/model/builder.py", line 209, in load_pretrained_model
    tokenizer, model, image_processor, _ = load_pretrained_model(args.model_path, args.model_base, model_name, device_map="auto")
  File "/scratch/nlp/patrick/codes/OminousLLM/intersuit/longva/model/builder.py", line 209, in load_pretrained_model
    tokenizer = AutoTokenizer.from_pretrained(model_path, use_fast=False)
    tokenizer = AutoTokenizer.from_pretrained(model_path, use_fast=False)
  File "/scratch/wangyuxuan1/.conda/envs/longva/lib/python3.10/site-packages/transformers/models/auto/tokenization_auto.py", line 834, in from_pretrained
  File "/scratch/wangyuxuan1/.conda/envs/longva/lib/python3.10/site-packages/transformers/models/auto/tokenization_auto.py", line 834, in from_pretrained
    tokenizer_config = get_tokenizer_config(pretrained_model_name_or_path, **kwargs)
    tokenizer_config = get_tokenizer_config(pretrained_model_name_or_path, **kwargs)
  File "/scratch/wangyuxuan1/.conda/envs/longva/lib/python3.10/site-packages/transformers/models/auto/tokenization_auto.py", line 666, in get_tokenizer_config
  File "/scratch/wangyuxuan1/.conda/envs/longva/lib/python3.10/site-packages/transformers/models/auto/tokenization_auto.py", line 666, in get_tokenizer_config
    resolved_config_file = cached_file(
    resolved_config_file = cached_file(
  File "/scratch/wangyuxuan1/.conda/envs/longva/lib/python3.10/site-packages/transformers/utils/hub.py", line 425, in cached_file
  File "/scratch/wangyuxuan1/.conda/envs/longva/lib/python3.10/site-packages/transformers/utils/hub.py", line 425, in cached_file
    raise EnvironmentError(
    raise EnvironmentError(
OSError: checkpoints/longva7b-llavanextsub10k-qwen2-ORNS is not a local folder and is not a valid model identifier listed on 'https://huggingface.co/models'
If this is a private repository, make sure to pass a token having permission to this repo either by logging in with `huggingface-cli login` or by passing `token=<your_token>`OSError: checkpoints/longva7b-llavanextsub10k-qwen2-ORNS is not a local folder and is not a valid model identifier listed on 'https://huggingface.co/models'
If this is a private repository, make sure to pass a token having permission to this repo either by logging in with `huggingface-cli login` or by passing `token=<your_token>`

Traceback (most recent call last):
  File "/scratch/wangyuxuan1/.conda/envs/longva/lib/python3.10/site-packages/huggingface_hub/utils/_errors.py", line 304, in hf_raise_for_status
    response.raise_for_status()
  File "/scratch/wangyuxuan1/.conda/envs/longva/lib/python3.10/site-packages/requests/models.py", line 1024, in raise_for_status
    raise HTTPError(http_error_msg, response=self)
requests.exceptions.HTTPError: 404 Client Error: Not Found for url: https://huggingface.co/checkpoints/longva7b-llavanextsub10k-qwen2-ORNS/resolve/main/tokenizer_config.json

The above exception was the direct cause of the following exception:

Traceback (most recent call last):
  File "/scratch/wangyuxuan1/.conda/envs/longva/lib/python3.10/site-packages/transformers/utils/hub.py", line 402, in cached_file
    resolved_file = hf_hub_download(
  File "/scratch/wangyuxuan1/.conda/envs/longva/lib/python3.10/site-packages/huggingface_hub/utils/_deprecation.py", line 101, in inner_f
    return f(*args, **kwargs)
  File "/scratch/wangyuxuan1/.conda/envs/longva/lib/python3.10/site-packages/huggingface_hub/utils/_validators.py", line 114, in _inner_fn
    return fn(*args, **kwargs)
  File "/scratch/wangyuxuan1/.conda/envs/longva/lib/python3.10/site-packages/huggingface_hub/file_download.py", line 1240, in hf_hub_download
    return _hf_hub_download_to_cache_dir(
  File "/scratch/wangyuxuan1/.conda/envs/longva/lib/python3.10/site-packages/huggingface_hub/file_download.py", line 1347, in _hf_hub_download_to_cache_dir
    _raise_on_head_call_error(head_call_error, force_download, local_files_only)
  File "/scratch/wangyuxuan1/.conda/envs/longva/lib/python3.10/site-packages/huggingface_hub/file_download.py", line 1854, in _raise_on_head_call_error
    raise head_call_error
  File "/scratch/wangyuxuan1/.conda/envs/longva/lib/python3.10/site-packages/huggingface_hub/file_download.py", line 1751, in _get_metadata_or_catch_error
    metadata = get_hf_file_metadata(
  File "/scratch/wangyuxuan1/.conda/envs/longva/lib/python3.10/site-packages/huggingface_hub/utils/_validators.py", line 114, in _inner_fn
    return fn(*args, **kwargs)
  File "/scratch/wangyuxuan1/.conda/envs/longva/lib/python3.10/site-packages/huggingface_hub/file_download.py", line 1673, in get_hf_file_metadata
Traceback (most recent call last):
  File "/scratch/wangyuxuan1/.conda/envs/longva/lib/python3.10/site-packages/huggingface_hub/utils/_errors.py", line 304, in hf_raise_for_status
    response.raise_for_status()
  File "/scratch/wangyuxuan1/.conda/envs/longva/lib/python3.10/site-packages/requests/models.py", line 1024, in raise_for_status
    r = _request_wrapper(
  File "/scratch/wangyuxuan1/.conda/envs/longva/lib/python3.10/site-packages/huggingface_hub/file_download.py", line 376, in _request_wrapper
    response = _request_wrapper(
  File "/scratch/wangyuxuan1/.conda/envs/longva/lib/python3.10/site-packages/huggingface_hub/file_download.py", line 400, in _request_wrapper
    raise HTTPError(http_error_msg, response=self)
requests.exceptions.HTTPError: 404 Client Error: Not Found for url: https://huggingface.co/checkpoints/longva7b-llavanextsub10k-qwen2-ORNS/resolve/main/tokenizer_config.json

The above exception was the direct cause of the following exception:

Traceback (most recent call last):
  File "/scratch/wangyuxuan1/.conda/envs/longva/lib/python3.10/site-packages/transformers/utils/hub.py", line 402, in cached_file
    hf_raise_for_status(response)
  File "/scratch/wangyuxuan1/.conda/envs/longva/lib/python3.10/site-packages/huggingface_hub/utils/_errors.py", line 352, in hf_raise_for_status
    resolved_file = hf_hub_download(
  File "/scratch/wangyuxuan1/.conda/envs/longva/lib/python3.10/site-packages/huggingface_hub/utils/_deprecation.py", line 101, in inner_f
    raise RepositoryNotFoundError(message, response) from e
huggingface_hub.utils._errors.RepositoryNotFoundError: 404 Client Error. (Request ID: Root=1-672a1e83-07f0a9514562c63a0e6f0c7f;819b5add-a903-4026-9354-cedd5b2ea187)

Repository Not Found for url: https://huggingface.co/checkpoints/longva7b-llavanextsub10k-qwen2-ORNS/resolve/main/tokenizer_config.json.
Please make sure you specified the correct `repo_id` and `repo_type`.
If you are trying to access a private or gated repo, make sure you are authenticated.

The above exception was the direct cause of the following exception:

Traceback (most recent call last):
    return f(*args, **kwargs)
  File "/scratch/wangyuxuan1/.conda/envs/longva/lib/python3.10/runpy.py", line 196, in _run_module_as_main
  File "/scratch/wangyuxuan1/.conda/envs/longva/lib/python3.10/site-packages/huggingface_hub/utils/_validators.py", line 114, in _inner_fn
    return fn(*args, **kwargs)
  File "/scratch/wangyuxuan1/.conda/envs/longva/lib/python3.10/site-packages/huggingface_hub/file_download.py", line 1240, in hf_hub_download
    return _run_code(code, main_globals, None,
  File "/scratch/wangyuxuan1/.conda/envs/longva/lib/python3.10/runpy.py", line 86, in _run_code
    exec(code, run_globals)
  File "/scratch/nlp/patrick/codes/OminousLLM/intersuit/longva/eval/model_videoqa_mc.py", line 243, in <module>
    run_inference(args)
  File "/scratch/nlp/patrick/codes/OminousLLM/intersuit/longva/eval/model_videoqa_mc.py", line 134, in run_inference
    return _hf_hub_download_to_cache_dir(
  File "/scratch/wangyuxuan1/.conda/envs/longva/lib/python3.10/site-packages/huggingface_hub/file_download.py", line 1347, in _hf_hub_download_to_cache_dir
    tokenizer, model, image_processor, _ = load_pretrained_model(args.model_path, args.model_base, model_name, device_map="auto")
  File "/scratch/nlp/patrick/codes/OminousLLM/intersuit/longva/model/builder.py", line 209, in load_pretrained_model
    tokenizer = AutoTokenizer.from_pretrained(model_path, use_fast=False)
  File "/scratch/wangyuxuan1/.conda/envs/longva/lib/python3.10/site-packages/transformers/models/auto/tokenization_auto.py", line 834, in from_pretrained
    _raise_on_head_call_error(head_call_error, force_download, local_files_only)
  File "/scratch/wangyuxuan1/.conda/envs/longva/lib/python3.10/site-packages/huggingface_hub/file_download.py", line 1854, in _raise_on_head_call_error
    tokenizer_config = get_tokenizer_config(pretrained_model_name_or_path, **kwargs)
  File "/scratch/wangyuxuan1/.conda/envs/longva/lib/python3.10/site-packages/transformers/models/auto/tokenization_auto.py", line 666, in get_tokenizer_config
    resolved_config_file = cached_file(
  File "/scratch/wangyuxuan1/.conda/envs/longva/lib/python3.10/site-packages/transformers/utils/hub.py", line 425, in cached_file
    raise head_call_error
  File "/scratch/wangyuxuan1/.conda/envs/longva/lib/python3.10/site-packages/huggingface_hub/file_download.py", line 1751, in _get_metadata_or_catch_error
    raise EnvironmentError(
OSError: checkpoints/longva7b-llavanextsub10k-qwen2-ORNS is not a local folder and is not a valid model identifier listed on 'https://huggingface.co/models'
If this is a private repository, make sure to pass a token having permission to this repo either by logging in with `huggingface-cli login` or by passing `token=<your_token>`
    metadata = get_hf_file_metadata(
  File "/scratch/wangyuxuan1/.conda/envs/longva/lib/python3.10/site-packages/huggingface_hub/utils/_validators.py", line 114, in _inner_fn
    return fn(*args, **kwargs)
  File "/scratch/wangyuxuan1/.conda/envs/longva/lib/python3.10/site-packages/huggingface_hub/file_download.py", line 1673, in get_hf_file_metadata
    r = _request_wrapper(
  File "/scratch/wangyuxuan1/.conda/envs/longva/lib/python3.10/site-packages/huggingface_hub/file_download.py", line 376, in _request_wrapper
    response = _request_wrapper(
  File "/scratch/wangyuxuan1/.conda/envs/longva/lib/python3.10/site-packages/huggingface_hub/file_download.py", line 400, in _request_wrapper
    hf_raise_for_status(response)
  File "/scratch/wangyuxuan1/.conda/envs/longva/lib/python3.10/site-packages/huggingface_hub/utils/_errors.py", line 352, in hf_raise_for_status
    raise RepositoryNotFoundError(message, response) from e
huggingface_hub.utils._errors.RepositoryNotFoundError: 404 Client Error. (Request ID: Root=1-672a1e83-7fba993039c3a9094ad3c883;4a7bcbd8-db2e-403e-be2f-e7fbb7d50c20)

Repository Not Found for url: https://huggingface.co/checkpoints/longva7b-llavanextsub10k-qwen2-ORNS/resolve/main/tokenizer_config.json.
Please make sure you specified the correct `repo_id` and `repo_type`.
If you are trying to access a private or gated repo, make sure you are authenticated.

The above exception was the direct cause of the following exception:

Traceback (most recent call last):
  File "/scratch/wangyuxuan1/.conda/envs/longva/lib/python3.10/runpy.py", line 196, in _run_module_as_main
    return _run_code(code, main_globals, None,
  File "/scratch/wangyuxuan1/.conda/envs/longva/lib/python3.10/runpy.py", line 86, in _run_code
    exec(code, run_globals)
  File "/scratch/nlp/patrick/codes/OminousLLM/intersuit/longva/eval/model_videoqa_mc.py", line 243, in <module>
    run_inference(args)
  File "/scratch/nlp/patrick/codes/OminousLLM/intersuit/longva/eval/model_videoqa_mc.py", line 134, in run_inference
    tokenizer, model, image_processor, _ = load_pretrained_model(args.model_path, args.model_base, model_name, device_map="auto")
  File "/scratch/nlp/patrick/codes/OminousLLM/intersuit/longva/model/builder.py", line 209, in load_pretrained_model
    tokenizer = AutoTokenizer.from_pretrained(model_path, use_fast=False)
  File "/scratch/wangyuxuan1/.conda/envs/longva/lib/python3.10/site-packages/transformers/models/auto/tokenization_auto.py", line 834, in from_pretrained
    tokenizer_config = get_tokenizer_config(pretrained_model_name_or_path, **kwargs)
  File "/scratch/wangyuxuan1/.conda/envs/longva/lib/python3.10/site-packages/transformers/models/auto/tokenization_auto.py", line 666, in get_tokenizer_config
    resolved_config_file = cached_file(
  File "/scratch/wangyuxuan1/.conda/envs/longva/lib/python3.10/site-packages/transformers/utils/hub.py", line 425, in cached_file
    raise EnvironmentError(
OSError: checkpoints/longva7b-llavanextsub10k-qwen2-ORNS is not a local folder and is not a valid model identifier listed on 'https://huggingface.co/models'
If this is a private repository, make sure to pass a token having permission to this repo either by logging in with `huggingface-cli login` or by passing `token=<your_token>`
/cm/local/apps/slurm/var/spool/job7896591/slurm_script: line 63: ./inputs/eval/videomme/longva7b-llavanextsub10k-qwen2-ORNS/merge.jsonl: No such file or directory
/cm/local/apps/slurm/var/spool/job7896591/slurm_script: line 66: ./inputs/eval/videomme/longva7b-llavanextsub10k-qwen2-ORNS/merge.jsonl: No such file or directory
/cm/local/apps/slurm/var/spool/job7896591/slurm_script: line 66: ./inputs/eval/videomme/longva7b-llavanextsub10k-qwen2-ORNS/merge.jsonl: No such file or directory
/cm/local/apps/slurm/var/spool/job7896591/slurm_script: line 66: ./inputs/eval/videomme/longva7b-llavanextsub10k-qwen2-ORNS/merge.jsonl: No such file or directory
/cm/local/apps/slurm/var/spool/job7896591/slurm_script: line 66: ./inputs/eval/videomme/longva7b-llavanextsub10k-qwen2-ORNS/merge.jsonl: No such file or directory
Traceback (most recent call last):
  File "/scratch/nlp/patrick/codes/OminousLLM/intersuit/scripts/eval/eval_acc.py", line 14, in <module>
    for line_idx, line in enumerate(open(args.src)):
FileNotFoundError: [Errno 2] No such file or directory: './inputs/eval/videomme/longva7b-llavanextsub10k-qwen2-ORNS/merge.jsonl'
